<robot name="letter_q">

    <link name="world"/>
    <link name="base_link">
       <inertial>
           <mass value="1.0"/>
           <origin rpy="0 0 0" xyz="0 0 0.025"/>
           <inertia ixx="0.0027" iyy="0.0027" izz="0.005" ixy="0" ixz="0" iyz="0"/>
       </inertial>
       <visual>
           <geometry>
               <box size = "1 4 0.05"/>
           </geometry>
           <material name="blue">
               <color rgba="0 0.5 1 1"/>
           </material>
           <origin rpy="0 0 0" xyz="0 0 0.025"/>
       </visual>
       <collision>
           <geometry>
               <box size = "1 4 0.05"/>
           </geometry>
           <origin rpy="0 0 0" xyz="0 0 0.025"/>
       </collision>
   </link>

   <joint name="fixed" type="fixed">
       <parent link="world"/>
       <child link="base_link"/>
   </joint>

   <link name="Q_letter_cil">
        <inertial>
           <mass value="1.0"/>
           <origin rpy="0 0 0" xyz="0 -1.3 0.1"/>
           <inertia ixx="0.0027" iyy="0.0027" izz="0.005" ixy="0" ixz="0" iyz="0"/>
       </inertial>
       <visual>
           <geometry>
               <cylinder radius="0.5" length="0.1"/>
           </geometry>
           <material name="silver">
               <color rgba="0.75 0.75 0.75 1"/>
           </material>
           <origin rpy="0 0 0" xyz="0 -1.3 0.1"/>
       </visual>
       <collision>
           <geometry>
               <cylinder radius="0.5" length="0.1"/>
           </geometry>
           <origin rpy="0 0 0" xyz="0 -1.3 0.1"/>
       </collision>
   </link>

    <joint name="slider_Q" type="prismatic">
       <parent link="base_link"/>
       <child link="Q_letter_cil"/>
       <axis xyz = "0 1 0"/>
       <limit lower="0" upper="1" velocity="100" effort="100"/>
   </joint>

    <link name="Q_letter_hole"/>
        <inertial>
           <mass value="1.0"/>
           <origin rpy="0 0 0" xyz="0 -1.3 0.1"/>
           <inertia ixx="0.0027" iyy="0.0027" izz="0.005" ixy="0" ixz="0" iyz="0"/>
       </inertial>
       <visual>
           <geometry>
               <cylinder radius="0.3" length="0.1"/>
           </geometry>
           <material name="transparant">
               <color rgba="0 0 0 0"/>
           </material>
           <origin rpy="0 0 0" xyz="0 -1.3 0.1"/>
       </visual>
       <collision>
           <geometry>
               <cylinder radius="0.5" length="0.1"/>
           </geometry>
           <origin rpy="0 0 0" xyz="0 -1.3 0.1"/>
       </collision>
   </link>

    <joint name="Q_hole" type="fixed">
       <parent link="Q_letter_cil"/>
       <child link="Q_letter_hole"/>
   </joint>

   <link name="Q_letter_tail"/>
        <inertial>
           <mass value="1.0"/>
           <origin rpy="0.5 0 0" xyz="0.25 -0.8 0.1"/>
           <inertia ixx="0.0027" iyy="0.0027" izz="0.005" ixy="0" ixz="0" iyz="0"/>
       </inertial>
       <visual>
           <geometry>
               <box size="0.1 0.3 0.1"/>
           </geometry>
           <material name="silver">
               <color rgba="0.75 0.75 0.75 1"/>
           </material>
           <origin rpy="0.5 0 0" xyz="0.25 -0.8 0.1"/>
       </visual>
       <collision>
           <geometry>
               <cylinder radius="0.5" length="0.1"/>
           </geometry>
           <origin rpy="0.5 0 0" xyz="0.25 -0.8 0.1"/>
       </collision>
   </link>

    <joint name="Q_tail" type="fixed">
       <parent link="Q_letter_cil"/>
       <child link="Q_letter_tail"/>
   </joint>

</robot>